#VRML_SIM R2019b utf8
WorldInfo {
  info [
    "Description"
    "Author: first name last name <e-mail>"
    "Date: DD MMM YYYY"
  ]
  physics "no_lift"
  basicTimeStep 1
  contactProperties [
    DEF CONTACT ContactProperties {
      coulombFriction [
        -1
      ]
    }
  ]
}
Viewpoint {
  orientation 0.025689927934339996 0.9993575903505217 0.02498868166845408 4.739357418715234
  position -6.025204678987203 1.2041365412127392 -0.02264043790324205
  follow "REGIS"
}
Background {
  skyColor [
    0.658824 0.827451 1
  ]
}
DirectionalLight {
  direction 1 -1 0
  castShadows TRUE
}
DirectionalLight {
  direction 0 0 1
}
DEF REGIS Robot {
  translation 0 1.62 0.00178
  rotation 1 0 0 0.05
  children [
    Transform {
      rotation 1 0 0 0
      children [
        DEF FOOT Group {
          children [
            Transform {
              children [
                Shape {
                  appearance Appearance {
                    material Material {
                    }
                  }
                  geometry Capsule {
                    height 0.16
                    radius 0.05
                  }
                }
              ]
            }
          ]
        }
        DEF SHIN Group {
          children [
            Transform {
              translation 0 -0.25 0
              children [
                DEF APPEARANCE_SHIN_LEFT Shape {
                  appearance Appearance {
                    material Material {
                    }
                  }
                  geometry Capsule {
                    height 0.35
                    radius 0.03
                  }
                }
              ]
            }
          ]
        }
        DEF THIGH Group {
          children [
            Transform {
              translation 0 -0.25 0
              children [
                DEF APPEARANCE_THIGH_LEFT Shape {
                  appearance Appearance {
                    material Material {
                    }
                  }
                  geometry Capsule {
                    height 0.35
                    radius 0.06
                  }
                }
              ]
            }
          ]
        }
        DEF JOINT Shape {
          appearance Appearance {
            material Material {
              diffuseColor 0.8 0 0
              transparency 0.01
            }
          }
          geometry Sphere {
            radius 0.07
          }
        }
      ]
    }
    DEF BRAINRECEIVER Receiver {
      name "BRAINRECEIVER"
      channel 3
    }
    DEF RECEIVER Receiver {
      name "RECEIVER"
      channel 1
    }
    DEF EMITTER Emitter {
      name "EMITTER"
    }
    DEF BRAINEMITTER Emitter {
      name "BRAINEMITTER"
      channel 2
    }
    DEF TRUNK Transform {
      translation 0 -0.19 0
      children [
        DEF TRUNK Shape {
          appearance Appearance {
            material Material {
            }
          }
          geometry Capsule {
            height 0.4
            radius 0.13
          }
        }
      ]
    }
    DEF LEFT_LEG Solid {
      translation 0.08 -0.4 0
      children [
        DEF LEFT_HIP Hinge2Joint {
          jointParameters HingeJointParameters {
          }
          device [
            PositionSensor {
              name "hip_l_POS"
            }
            RotationalMotor {
              name "hip_l"
              minPosition -3.1415
              maxPosition 3.1415
              maxTorque 400
            }
          ]
          endPoint DEF LEFT_THIGH Solid {
            rotation -1 0 0 0.009600000000003089
            children [
              Transform {
                translation 0 -0.5 0
                children [
                  DEF LEFT_KNEE HingeJoint {
                    jointParameters HingeJointParameters {
                    }
                    device [
                      RotationalMotor {
                        name "knee_l"
                        minPosition -3.1415
                        maxPosition 3.1415
                        maxTorque 400
                      }
                      PositionSensor {
                        name "knee_l_POS"
                      }
                    ]
                    endPoint DEF LEFT_SHIN Solid {
                      rotation 1 0 0 0.019800000000003745
                      children [
                        USE JOINT
                        USE SHIN
                        Transform {
                          translation 0 -0.5 0
                          children [
                            DEF LEFT_ANKLE HingeJoint {
                              jointParameters HingeJointParameters {
                              }
                              device [
                                RotationalMotor {
                                  name "ankle_l"
                                  minPosition -3.1415
                                  maxPosition 3.1415
                                  maxTorque 400
                                }
                                PositionSensor {
                                  name "ankle_l_POS"
                                }
                              ]
                              endPoint DEF LEFT_FOOT Solid {
                                rotation -1 0 0 0.055599999999999705
                                children [
                                  Transform {
                                    translation 0 -0.075 0.06
                                    rotation 1 0 0 1.57
                                    children [
                                      DEF SENSOR_HEEL_LEFT TouchSensor {
                                        translation 0 -0.075 0
                                        name "SENSOR_HEEL_LEFT"
                                        boundingObject Transform {
                                          rotation 1 0 0 0
                                          children [
                                            Sphere {
                                              radius 0.05
                                            }
                                          ]
                                        }
                                        physics Physics {
                                          density -1
                                          mass 1e-08
                                        }
                                        type "force-3d"
                                        lookupTable []
                                      }
                                      DEF SENSOR_TOE_LEFT TouchSensor {
                                        translation 0 0.075 0
                                        name "SENSOR_TOE_LEFT"
                                        boundingObject Transform {
                                          rotation 1 0 0 1.57
                                          children [
                                            Sphere {
                                              radius 0.05
                                            }
                                          ]
                                        }
                                        physics Physics {
                                          density -1
                                          mass 1e-08
                                        }
                                        type "force-3d"
                                        lookupTable []
                                      }
                                      USE FOOT
                                    ]
                                  }
                                  USE JOINT
                                ]
                                name "left foot"
                                physics Physics {
                                  density -1
                                  mass 1.25
                                  centerOfMass [
                                    0 0 0.02
                                  ]
                                  inertiaMatrix [
                                    0.005 0.005 0.005
                                    0 0 0
                                  ]
                                }
                              }
                            }
                          ]
                        }
                      ]
                      name "left shin"
                      boundingObject USE SHIN
                      physics Physics {
                        density -1
                        mass 3.5
                        centerOfMass [
                          0 -0.2 0
                        ]
                        inertiaMatrix [
                          0.05 0.05 0.05
                          0 0 0
                        ]
                      }
                    }
                  }
                ]
              }
              USE JOINT
              USE THIGH
            ]
            name "left thigh"
            boundingObject USE THIGH
            physics Physics {
              density -1
              mass 8.5
              centerOfMass [
                0 -0.2 0
              ]
              inertiaMatrix [
                0.15 0.15 0.15
                0 0 0
              ]
            }
          }
        }
      ]
      name "left leg"
      boundingObject Sphere {
        radius 0.001
      }
      physics Physics {
        density 1
      }
    }
    DEF RIGHT_LEG Solid {
      translation -0.08 -0.4 0
      children [
        DEF RIGHT_HIP Hinge2Joint {
          jointParameters HingeJointParameters {
          }
          device [
            PositionSensor {
              name "hip_r_POS"
            }
            RotationalMotor {
              name "hip_r"
              maxVelocity 100
              minPosition -3.1415
              maxPosition 3.1415
              maxTorque 400
            }
          ]
          endPoint DEF RIGHT_THIGH Solid {
            rotation -1 0 0 0.009600000000003089
            children [
              Transform {
                translation 0 -0.5 0
                children [
                  DEF RIGHT_KNEE HingeJoint {
                    jointParameters HingeJointParameters {
                    }
                    device [
                      RotationalMotor {
                        name "knee_r"
                        controlPID 100 0 0
                        maxVelocity 100
                        minPosition -3.1415
                        maxPosition 3.1415
                        maxTorque 400
                      }
                      PositionSensor {
                        name "knee_r_POS"
                      }
                    ]
                    endPoint DEF RIGHT_SHIN Solid {
                      rotation 1 0 0 0.019800000000003745
                      children [
                        USE JOINT
                        USE SHIN
                        Transform {
                          translation 0 -0.5 0
                          children [
                            DEF RIGHT_ANKLE HingeJoint {
                              jointParameters HingeJointParameters {
                              }
                              device [
                                RotationalMotor {
                                  name "ankle_r"
                                  controlPID 100 0 0
                                  maxVelocity 100
                                  minPosition -3.1415
                                  maxPosition 3.1415
                                  maxTorque 400
                                }
                                PositionSensor {
                                  name "ankle_r_POS"
                                }
                              ]
                              endPoint DEF RIGHT_FOOT Solid {
                                rotation -1 0 0 0.055599999999999705
                                children [
                                  Transform {
                                    translation 0 -0.075 0.06
                                    rotation 1 0 0 1.57
                                    children [
                                      DEF SENSOR_HEEL_RIGHT TouchSensor {
                                        translation 0 -0.075 0
                                        name "SENSOR_HEEL_RIGHT"
                                        boundingObject Transform {
                                          rotation 1 0 0 0
                                          children [
                                            Sphere {
                                              radius 0.05
                                            }
                                          ]
                                        }
                                        physics Physics {
                                          density -1
                                          mass 1e-08
                                        }
                                        type "force-3d"
                                        lookupTable []
                                      }
                                      DEF SENSOR_TOE_RIGHT TouchSensor {
                                        translation 0 0.075 0
                                        name "SENSOR_TOE_RIGHT"
                                        boundingObject Transform {
                                          rotation 1 0 0 1.57
                                          children [
                                            Sphere {
                                              radius 0.05
                                            }
                                          ]
                                        }
                                        physics Physics {
                                          density -1
                                          mass 1e-08
                                        }
                                        type "force-3d"
                                        lookupTable []
                                      }
                                      USE FOOT
                                    ]
                                  }
                                  USE JOINT
                                ]
                                name "right foot"
                                physics Physics {
                                  density -1
                                  mass 1.25
                                  centerOfMass [
                                    0 0 0.02
                                  ]
                                  inertiaMatrix [
                                    0.005 0.005 0.005
                                    0 0 0
                                  ]
                                }
                              }
                            }
                          ]
                        }
                      ]
                      name "right shin"
                      boundingObject USE SHIN
                      physics Physics {
                        density -1
                        mass 3.5
                        centerOfMass [
                          0 -0.2 0
                        ]
                        inertiaMatrix [
                          0.05 0.05 0.05
                          0 0 0
                        ]
                      }
                    }
                  }
                ]
              }
              USE JOINT
              USE THIGH
            ]
            name "right thigh"
            boundingObject USE THIGH
            physics Physics {
              density -1
              mass 8.5
              centerOfMass [
                0 -0.2 0
              ]
              inertiaMatrix [
                0.15 0.15 0.15
                0 0 0
              ]
            }
          }
        }
      ]
      name "right leg"
      boundingObject Sphere {
        radius 0.001
      }
      physics Physics {
        density 1
      }
    }
  ]
  name "REGIS"
  boundingObject DEF TRUNK Transform {
    translation 0 -0.19 0
    children [
      DEF TRUNK Shape {
        geometry Capsule {
          height 0.4
          radius 0.13
          subdivision 16
        }
      }
    ]
  }
  physics Physics {
    density -1
    mass 53.5
    centerOfMass [
      0 -0.05 0
    ]
    inertiaMatrix [
      3 3 3
      0 0 0
    ]
  }
  controller "Balance_paper_single1"
  supervisor TRUE
}
DEF BRAIN Supervisor {
  children [
    Emitter {
      channel 3
    }
    Receiver {
      channel 2
    }
  ]
  name "brain"
  controllerArgs "--random-seed-port=5662 --action-dim=23"
}
DEF MOVING_GROUND Robot {
  translation 0 0.05 0
  children [
    DEF GROUND Solid {
      children [
        SliderJoint {
          jointParameters JointParameters {
          }
          device [
            PositionSensor {
              name "GROUND_GROUND_POS"
            }
            LinearMotor {
              name "GROUND_GROUND_MOT"
              controlPID 10000 0 0
              maxForce 1000000
            }
          ]
          endPoint Solid {
            children [
              Shape {
                appearance Appearance {
                  material Material {
                    diffuseColor 0.8 0 0
                  }
                }
                geometry Box {
                  size 1 0.1 1
                }
              }
            ]
            boundingObject Shape {
              appearance Appearance {
              }
              geometry Box {
                size 1 0.1 1
              }
            }
            physics Physics {
              density -1
              mass 1000
              damping Damping {
                linear 1
              }
            }
          }
        }
        DEF APPEARANCE_GROUND Transform {
          scale 3 1 3
          children [
            Shape {
              appearance Appearance {
                material Material {
                  diffuseColor 1 1 1
                }
                texture ImageTexture {
                  url [
                    "textures/BIOROB1.jpg"
                  ]
                }
                textureTransform TextureTransform {
                  scale 100 300
                }
              }
              geometry Plane {
                size 500 1155
              }
            }
          ]
        }
      ]
      name "GROUND"
      boundingObject Plane {
        size 300 300
      }
    }
  ]
  controller "MovingGroundfull"
  supervisor TRUE
}
Robot {
  controller "killAfterTime"
  supervisor TRUE
}
